Workbook

Sheet Tables
A1: datasets | B1: credit risk | C1: bank customers | D1: FRED-QD | E1: FRED-MD
A2: potential target variable(s) | B2: =COUNTIFS('Column Type Key'!$A$2:$A$392,"credit risk",'Column Type Key'!$D$2:$D$392,"Y") -> 1 | C2: =COUNTIFS('Column Type Key'!$A$2:$A$392,"bank customers",'Column Type Key'!$D$2:$D$392,"Y") -> 0 | D2: =COUNTIFS('Column Type Key'!$A$2:$A$392,"FRED-QD",'Column Type Key'!$D$2:$D$392,"Y") -> 5 | E2: =COUNTIFS('Column Type Key'!$A$2:$A$392,"FRED-MD",'Column Type Key'!$D$2:$D$392,"Y") -> 4
A3: columns | B3: =COUNTIF('Column Type Key'!$A$2:$A$392,"credit risk") -> 12 | C3: =COUNTIF('Column Type Key'!$A$2:$A$392,"bank customers") -> 6 | D3: =COUNTIF('Column Type Key'!$A$2:$A$392,"FRED-QD") -> 246 | E3: =COUNTIF('Column Type Key'!$A$2:$A$392,"FRED-MD") -> 127
A4: row count | B4: 32581 | C4: 100 | D4: 269 | E4: 806
A5: Table 1 - A count of each dataset’s columns and row counts (yellow = fill in FRED row counts)
A7: types of variables | B7: credit risk | C7: bank customers | D7: FRED-QD | E7: FRED-MD
A8: discrete (binary) | B8: =COUNTIFS('Column Type Key'!$A$2:$A$392,"credit risk",'Column Type Key'!$C$2:$C$392,"discrete (binary)") -> 2 | C8: =COUNTIFS('Column Type Key'!$A$2:$A$392,"bank customers",'Column Type Key'!$C$2:$C$392,"discrete (binary)") -> 0 | D8: =COUNTIFS('Column Type Key'!$A$2:$A$392,"FRED-QD",'Column Type Key'!$C$2:$C$392,"discrete (binary)") -> 0 | E8: =COUNTIFS('Column Type Key'!$A$2:$A$392,"FRED-MD",'Column Type Key'!$C$2:$C$392,"discrete (binary)") -> 0
A9: discrete (integer) | B9: =COUNTIFS('Column Type Key'!$A$2:$A$392,"credit risk",'Column Type Key'!$C$2:$C$392,"discrete (integer)") -> 3 | C9: =COUNTIFS('Column Type Key'!$A$2:$A$392,"bank customers",'Column Type Key'!$C$2:$C$392,"discrete (integer)") -> 0 | D9: =COUNTIFS('Column Type Key'!$A$2:$A$392,"FRED-QD",'Column Type Key'!$C$2:$C$392,"discrete (integer)") -> 0 | E9: =COUNTIFS('Column Type Key'!$A$2:$A$392,"FRED-MD",'Column Type Key'!$C$2:$C$392,"discrete (integer)") -> 0
A10: numeric continuous | B10: =COUNTIFS('Column Type Key'!$A$2:$A$392,"credit risk",'Column Type Key'!$C$2:$C$392,"numeric continuous") -> 4 | C10: =COUNTIFS('Column Type Key'!$A$2:$A$392,"bank customers",'Column Type Key'!$C$2:$C$392,"numeric continuous") -> 0 | D10: =COUNTIFS('Column Type Key'!$A$2:$A$392,"FRED-QD",'Column Type Key'!$C$2:$C$392,"numeric continuous") -> 245 | E10: =COUNTIFS('Column Type Key'!$A$2:$A$392,"FRED-MD",'Column Type Key'!$C$2:$C$392,"numeric continuous") -> 126
A11: categorical (nominal) | B11: =COUNTIFS('Column Type Key'!$A$2:$A$392,"credit risk",'Column Type Key'!$C$2:$C$392,"categorical (nominal)") -> 2 | C11: =COUNTIFS('Column Type Key'!$A$2:$A$392,"bank customers",'Column Type Key'!$C$2:$C$392,"categorical (nominal)") -> 1 | D11: =COUNTIFS('Column Type Key'!$A$2:$A$392,"FRED-QD",'Column Type Key'!$C$2:$C$392,"categorical (nominal)") -> 0 | E11: =COUNTIFS('Column Type Key'!$A$2:$A$392,"FRED-MD",'Column Type Key'!$C$2:$C$392,"categorical (nominal)") -> 0
A12: categorical (ordinal) | B12: =COUNTIFS('Column Type Key'!$A$2:$A$392,"credit risk",'Column Type Key'!$C$2:$C$392,"categorical (ordinal)") -> 1 | C12: =COUNTIFS('Column Type Key'!$A$2:$A$392,"bank customers",'Column Type Key'!$C$2:$C$392,"categorical (ordinal)") -> 0 | D12: =COUNTIFS('Column Type Key'!$A$2:$A$392,"FRED-QD",'Column Type Key'!$C$2:$C$392,"categorical (ordinal)") -> 0 | E12: =COUNTIFS('Column Type Key'!$A$2:$A$392,"FRED-MD",'Column Type Key'!$C$2:$C$392,"categorical (ordinal)") -> 0
A13: identifier | B13: =COUNTIFS('Column Type Key'!$A$2:$A$392,"credit risk",'Column Type Key'!$C$2:$C$392,"identifier") -> 0 | C13: =COUNTIFS('Column Type Key'!$A$2:$A$392,"bank customers",'Column Type Key'!$C$2:$C$392,"identifier") -> 3 | D13: =COUNTIFS('Column Type Key'!$A$2:$A$392,"FRED-QD",'Column Type Key'!$C$2:$C$392,"identifier") -> 0 | E13: =COUNTIFS('Column Type Key'!$A$2:$A$392,"FRED-MD",'Column Type Key'!$C$2:$C$392,"identifier") -> 0
A14: date | B14: =COUNTIFS('Column Type Key'!$A$2:$A$392,"credit risk",'Column Type Key'!$C$2:$C$392,"date") -> 0 | C14: =COUNTIFS('Column Type Key'!$A$2:$A$392,"bank customers",'Column Type Key'!$C$2:$C$392,"date") -> 2 | D14: =COUNTIFS('Column Type Key'!$A$2:$A$392,"FRED-QD",'Column Type Key'!$C$2:$C$392,"date") -> 1 | E14: =COUNTIFS('Column Type Key'!$A$2:$A$392,"FRED-MD",'Column Type Key'!$C$2:$C$392,"date") -> 1
A15: total | B15: =SUM(B8:B14) -> 12 | C15: =SUM(C8:C14) -> 6 | D15: =SUM(D8:D14) -> 246 | E15: =SUM(E8:E14) -> 127
A16: Table 2 - The types of variables available in each dataset color coded for Table 3
A17: FRED target variables (red) are macro series related to the credit risk dataset. Delinquency/charge-off add-ons (closest to loan_status) are on the FRED Dictionary tab.
A19: credit risk | B19: bank customers | C19: FRED-QD | D19: FRED-MD
A20: person_age | B20: CustomerID | C20: sasdate | D20: sasdate
A21: person_income | B21: BirthDate | C21: GDPC1 | D21: RPI
A22: person_home_ownership | B22: SSN | C22: PCECC96 | D22: W875RX1
A23: person_emp_length | B23: AccountID | C23: PCDGx | D23: DPCERA3M086SBEA
A24: loan_intent | B24: AccountOpened | C24: PCESVx | D24: CMRMTSPLx
A25: loan_grade | B25: AccountType | C25: PCNDx | D25: RETAILx
A26: loan_amnt | C26: GPDIC1 | D26: INDPRO
A27: loan_int_rate | C27: FPIx | D27: IPFPNSS
A28: loan_status | C28: Y033RC1Q027SBEAx | D28: IPFINAL
A29: loan_percent_income | C29: PNFIx | D29: IPCONGD
A30: cb_person_default_on_file | C30: PRFIx | D30: IPDCONGD
A31: cb_person_cred_hist_length | C31: A014RE1Q156NBEA | D31: IPNCONGD
C32: GCEC1 | D32: IPBUSEQ
C33: A823RL1Q225SBEA | D33: IPMAT
C34: FGRECPTx | D34: IPDMAT
C35: SLCEx | D35: IPNMAT
C36: EXPGSC1 | D36: IPMANSICS
C37: IMPGSC1 | D37: IPB51222S
C38: DPIC96 | D38: IPFUELS
C39: OUTNFB | D39: CUMFNS
C40: OUTBS | D40: HWI
C41: OUTMS | D41: HWIURATIO
C42: INDPRO | D42: CLF16OV
...

Sheet FRED Dictionary
A1: dataset | B1: original name | C1: new name | D1: group | E1: description | F1: indicator timing | G1: timing basis | H1: variable type | I1: potential target? | J1: link to credit risk dataset | K1: data available (FRED)
A2: FRED-QD | B2: sasdate | C2: date | D2: Date | E2: Observation date (quarter start for QD, month start for MD) | F2: n/a | G2: Time index | H2: date
A3: FRED-QD | B3: GDPC1 | C3: gdp_real | D3: 1 - NIPA (output & income) | E3: Real Gross Domestic Product | F3: Coincident | G3: Moves with current activity (output, jobs, income, sales) | H3: numeric continuous
A4: FRED-QD | B4: PCECC96 | C4: pce_real | D4: 1 - NIPA (output & income) | E4: Real Personal Consumption Expenditures | F4: Coincident | G4: Moves with current activity (output, jobs, income, sales) | H4: numeric continuous
A5: FRED-QD | B5: PCDGx | C5: pce_durable | D5: 1 - NIPA (output & income) | E5: Real PCE: Durable Goods | F5: Coincident | G5: Moves with current activity (output, jobs, income, sales) | H5: numeric continuous
A6: FRED-QD | B6: PCESVx | C6: pce_services | D6: 1 - NIPA (output & income) | E6: Real PCE: Services | F6: Coincident | G6: Moves with current activity (output, jobs, income, sales) | H6: numeric continuous
A7: FRED-QD | B7: PCNDx | C7: pce_nondurable | D7: 1 - NIPA (output & income) | E7: Real PCE: Nondurable Goods | F7: Coincident | G7: Moves with current activity (output, jobs, income, sales) | H7: numeric continuous
A8: FRED-QD | B8: GPDIC1 | C8: invest_gross | D8: 1 - NIPA (output & income) | E8: Real Gross Private Domestic Investment | F8: Coincident | G8: Moves with current activity (output, jobs, income, sales) | H8: numeric continuous
A9: FRED-QD | B9: FPIx | C9: invest_fixed | D9: 1 - NIPA (output & income) | E9: Real Private Fixed Investment | F9: Coincident | G9: Moves with current activity (output, jobs, income, sales) | H9: numeric continuous
A10: FRED-QD | B10: Y033RC1Q027SBEAx | C10: invest_equip | D10: 1 - NIPA (output & income) | E10: Real Gross Private Domestic Investment: Nonresidential Equipment | F10: Coincident | G10: Moves with current activity (output, jobs, income, sales) | H10: numeric continuous
A11: FRED-QD | B11: PNFIx | C11: invest_nonres | D11: 1 - NIPA (output & income) | E11: Real Private Fixed Investment: Nonresidential | F11: Coincident | G11: Moves with current activity (output, jobs, income, sales) | H11: numeric continuous
A12: FRED-QD | B12: PRFIx | C12: invest_res | D12: 1 - NIPA (output & income) | E12: Real Private Fixed Investment: Residential | F12: Leading | G12: Residential investment typically turns first in a cycle | H12: numeric continuous
A13: FRED-QD | B13: A014RE1Q156NBEA | C13: invest_inv_chg | D13: 1 - NIPA (output & income) | E13: Shares of GDP: Change in Private Inventories | F13: Coincident | G13: Moves with current activity (output, jobs, income, sales) | H13: numeric continuous
... A184: FRED-QD | B184: BAA | C184: rate_corp_baa | D184: 8 - Interest Rates | E184: Moody's Seasoned Baa Corporate Bond Yield | F184: Leading | G184: Market yields reflect expected rates and risk | H184: numeric continuous
A185: FRED-QD | B185: BAA10YM | C185: spr_baa_10y | D185: 8 - Interest Rates | E185: Spread: Baa Corporate Yield minus 10-Year Treasury | F185: Leading | G185: Rate spreads / yield curve anticipate growth and credit stress | H185: numeric continuous | I185: Y | J185: Credit risk premium; moves with default risk and lending rates (loan_int_rate)
A186: FRED-QD | B186: MORTG10YRx | C186: spr_mort_10y | D186: 8 - Interest Rates | E186: Spread: 30-Year Mortgage Rate minus 10-Year Treasury | F186: Leading | G186: Rate spreads / yield curve anticipate growth and credit stress | H186: numeric continuous
A187: FRED-QD | B187: TB6M3Mx | C187: spr_6m_3m | D187: 8 - Interest Rates | E187: Spread: 6-Month minus 3-Month T-Bill | F187: Leading | G187: Rate spreads / yield curve anticipate growth and credit stress | H187: numeric continuous
A188: FRED-QD | B188: GS1TB3Mx | C188: spr_1y_3m | D188: 8 - Interest Rates | E188: Spread: 1-Year Treasury minus 3-Month T-Bill | F188: Leading | G188: Rate spreads / yield curve anticipate growth and credit stress | H188: numeric continuous
A189: FRED-QD | B189: GS10TB3Mx | C189: spr_10y_3m | D189: 8 - Interest Rates | E189: Spread: 10-Year Treasury minus 3-Month T-Bill | F189: Leading | G189: Rate spreads / yield curve anticipate growth and credit stress | H189: numeric continuous
A190: FRED-QD | B190: CPF3MTB3Mx | C190: spr_cp_tbill | D190: 8 - Interest Rates | E190: Spread: 3-Month Commercial Paper minus 3-Month T-Bill | F190: Leading | G190: Rate spreads / yield curve anticipate growth and credit stress | H190: numeric continuous
A191: FRED-QD | B191: GS5 | C191: rate_tsy_5y | D191: 8 - Interest Rates | E191: 5-Year Treasury Constant Maturity Rate | F191: Leading | G191: Market yields reflect expected rates and risk | H191: numeric continuous
A192: FRED-QD | B192: TB3SMFFM | C192: spr_3m_ff | D192: 8 - Interest Rates | E192: Spread: 3-Month T-Bill minus Fed Funds | F192: Leading | G192: Rate spreads / yield curve anticipate growth and credit stress | H192: numeric continuous
A193: FRED-QD | B193: T5YFFM | C193: spr_5y_ff | D193: 8 - Interest Rates | E193: Spread: 5-Year Treasury minus Fed Funds | F193: Leading | G193: Rate spreads / yield curve anticipate growth and credit stress | H193: numeric continuous
A194: FRED-QD | B194: AAAFFM | C194: spr_aaa_ff | D194: 8 - Interest Rates | E194: Spread: Moody's Aaa Corporate minus Fed Funds | F194: Leading | G194: Rate spreads / yield curve anticipate growth and credit stress | H194: numeric continuous
A195: FRED-QD | B195: CP3M | C195: rate_cp_3m | D195: 8 - Interest Rates | E195: 3-Month AA Financial Commercial Paper Rate | F195: Leading | G195: Market yields reflect expected rates and risk | H195: numeric continuous
A196: FRED-QD | B196: COMPAPFF | C196: spr_cp_ff | D196: 8 - Interest Rates | E196: Spread: 3-Month Commercial Paper minus Fed Funds | F196: Leading | G196: Rate spreads / yield curve anticipate growth and credit stress | H196: numeric continuous
A197: FRED-QD | B197: BOGMBASEREALx | C197: money_base_real | D197: 9 - Money & Credit | E197: Real Monetary Base | F197: Coincident | G197: Moves with current activity (output, jobs, income, sales) | H197: numeric continuous
... A201: FRED-QD | B201: CONSUMERx | C201: credit_cons_banks | D201: 9 - Money & Credit | E201: Real Consumer Loans at All Commercial Banks | F201: Lagging | G201: Loan balances respond after spending/income | H201: numeric continuous
A202: FRED-QD | B202: NONREVSLx | C202: credit_nonrevolving | D202: 9 - Money & Credit | E202: Real Nonrevolving Consumer Credit Outstanding | F202: Lagging | G202: Loan balances respond after spending/income | H202: numeric continuous | I202: Y | J202: Volume of nonrevolving consumer loans (personal/education/medical); ties to loan_amnt
A203: FRED-QD | B203: REALLNx | C203: credit_real_estate | D203: 9 - Money & Credit | E203: Real Real Estate Loans at All Commercial Banks | F203: Lagging | G203: Loan balances respond after spending/income | H203: numeric continuous
A204: FRED-QD | B204: REVOLSLx | C204: credit_revolving | D204: 9 - Money & Credit | E204: Real Revolving Consumer Credit Outstanding | F204: Lagging | G204: Loan balances respond after spending/income | H204: numeric continuous
A205: FRED-QD | B205: TOTALSLx | C205: credit_cons_total | D205: 9 - Money & Credit | E205: Real Total Consumer Credit Outstanding | F205: Lagging | G205: Loan balances respond after spending/income | H205: numeric continuous
A206: FRED-QD | B206: DRIWCIL | C206: credit_willing_cons | D206: 9 - Money & Credit | E206: Senior Loan Officer Survey: Net % of Banks More Willing to Make Consumer Installment Loans | F206: Leading | G206: Lender survey on upcoming credit supply | H206: numeric continuous | I206: Y | J206: Banks' willingness to make consumer installment loans; ties to approval/loan_grade
A207: FRED-QD | B207: TOTRESNS | C207: money_reserves | D207: 9 - Money & Credit | E207: Total Reserves of Depository Institutions | F207: Coincident | G207: Moves with current activity (output, jobs, income, sales) | H207: numeric continuous
A208: FRED-QD | B208: NONBORRES | C208: money_reserves_nb | D208: 9 - Money & Credit | E208: Nonborrowed Reserves of Depository Institutions | F208: Coincident | G208: Moves with current activity (output, jobs, income, sales) | H208: numeric continuous
A209: FRED-QD | B209: DTCOLNVHFNM | C209: credit_auto_loans | D209: 9 - Money & Credit | E209: Consumer Motor Vehicle Loans Outstanding (finance companies) | F209: Lagging | G209: Loan balances respond after spending/income | H209: numeric continuous
A210: FRED-QD | B210: DTCTHFNM | C210: credit_cons_fincos | D210: 9 - Money & Credit | E210: Total Consumer Loans & Leases Outstanding (finance companies) | F210: Lagging | G210: Loan balances respond after spending/income | H210: numeric continuous
A211: FRED-QD | B211: INVEST | C211: bank_securities | D211: 9 - Money & Credit | E211: Securities in Bank Credit at All Commercial Banks | F211: Lagging | G211: Loan balances respond after spending/income | H211: numeric continuous
A212: FRED-QD | B212: CONSPIx | C212: credit_to_income | D212: 9 - Money & Credit | E212: Nonrevolving Consumer Credit to Personal Income (ratio) | F212: Lagging | G212: Loan balances respond after spending/income | H212: numeric continuous | I212: Y | J212: Consumer credit-to-income ratio; macro analogue of loan_percent_income
A213: FRED-QD | B213: TABSHNOx | C213: hh_assets | D213: 10 - Household Balance Sheets | E213: Real Total Assets of Households & Nonprofits | F213: Lagging | G213: Balance sheets reflect accumulated past activity | H213: numeric continuous
...

Sheet Column Type Key
A1: dataset | B1: column | C1: variable type | D1: target? (Y) | F1: Edit column C (type) or D (mark Y for target) here — Tables 1 and 2 recount automatically. Table 3 colors are static.
A2: credit risk | B2: person_age | C2: discrete (integer)
A3: credit risk | B3: person_income | C3: numeric continuous
A4: credit risk | B4: person_home_ownership | C4: categorical (nominal)
A5: credit risk | B5: person_emp_length | C5: discrete (integer)
A6: credit risk | B6: loan_intent | C6: categorical (nominal)
A7: credit risk | B7: loan_grade | C7: categorical (ordinal)
A8: credit risk | B8: loan_amnt | C8: numeric continuous
A9: credit risk | B9: loan_int_rate | C9: numeric continuous
A10: credit risk | B10: loan_status | C10: discrete (binary) | D10: Y
A11: credit risk | B11: loan_percent_income | C11: numeric continuous
A12: credit risk | B12: cb_person_default_on_file | C12: discrete (binary)
A13: credit risk | B13: cb_person_cred_hist_length | C13: discrete (integer)
A14: bank customers | B14: CustomerID | C14: identifier
A15: bank customers | B15: BirthDate | C15: date
A16: bank customers | B16: SSN | C16: identifier
A17: bank customers | B17: AccountID | C17: identifier
A18: bank customers | B18: AccountOpened | C18: date
A19: bank customers | B19: AccountType | C19: categorical (nominal)
A20: FRED-QD | B20: sasdate | C20: date
A21: FRED-QD | B21: GDPC1 | C21: numeric continuous
A22: FRED-QD | B22: PCECC96 | C22: numeric continuous
... A171: FRED-QD | B171: BAA | C171: numeric continuous
A172: FRED-QD | B172: BAA10YM | C172: numeric continuous | D172: Y
A173: FRED-QD | B173: MORTG10YRx | C173: numeric continuous
A174: FRED-QD | B174: TB6M3Mx | C174: numeric continuous
A175: FRED-QD | B175: GS1TB3Mx | C175: numeric continuous
A176: FRED-QD | B176: GS10TB3Mx | C176: numeric continuous
A177: FRED-QD | B177: CPF3MTB3Mx | C177: numeric continuous
A178: FRED-QD | B178: BOGMBASEREALx | C178: numeric continuous
A179: FRED-QD | B179: M1REAL | C179: numeric continuous
A180: FRED-QD | B180: M2REAL | C180: numeric continuous
A181: FRED-QD | B181: BUSLOANSx | C181: numeric continuous
A182: FRED-QD | B182: CONSUMERx | C182: numeric continuous
A183: FRED-QD | B183: NONREVSLx | C183: numeric continuous | D183: Y
A184: FRED-QD | B184: REALLNx | C184: numeric continuous
A185: FRED-QD | B185: REVOLSLx | C185: numeric continuous
A186: FRED-QD | B186: TOTALSLx | C186: numeric continuous
A187: FRED-QD | B187: DRIWCIL | C187: numeric continuous | D187: Y
A188: FRED-QD | B188: TABSHNOx | C188: numeric continuous
...
